<?xml version='1.0' encoding='utf-8'?>
    <robot name="sirius">
    <link name="base_link"/>

    <joint name="base_link_to_Frame" type="fixed">
        <parent link="base_link"/>
        <child link="Frame"/>
        <!-- 上に455mm, Z軸で１８０度回転 -->
        <origin xyz="0 0 0.455" rpy="0 0 3.141592653589793"/>
    </joint>

    <link name="MDF">
        <inertial>
            <origin xyz="0.0 0.0 -0.1875" rpy="0.0 0.0 0.0" />
            <mass value="7.300499999999998" />
            <inertia ixx="0.058480046875000025" iyy="0.21903020937500006" izz="0.2774798375" ixy="0.0" iyz="1.4279066817834973e-18" ixz="1.4279066817834973e-18" />
        </inertial>
        <visual name="MDF_visual">
            <origin xyz="0.0 0.0 0.0" rpy="0.0 0.0 0.0" />
            <geometry>
                <mesh filename="package://Sirius_description/meshes/MDF.stl" scale="0.001 0.001 0.001" />
            </geometry>
        </visual>
        <collision name="MDF_collision">
            <origin xyz="0.0 0.0 0.0" rpy="0.0 0.0 0.0" />
            <geometry>
                <mesh filename="package://Sirius_description/meshes/MDF.stl" scale="0.001 0.001 0.001" />
            </geometry>
        </collision>
    </link>
    <link name="Right_Wheel">
        <inertial>
            <origin xyz="-2.4424906541753444e-17 3.552713678800501e-17 0.06249999999999993" rpy="0.0 -0.0 0.0" />
            <mass value="100.05890789374806" />
            <inertia ixx="0.9387204983052868" iyy="0.9387204983053428" izz="1.6349121401939106" ixy="1.9984014443252818e-15" iyz="0.0" ixz="-1.1102230246251565e-16" />
        </inertial>
        <visual name="Right_Wheel_visual">
            <origin xyz="0.015 -0.27 -0.18" rpy="1.5707963267948966 -0.0 0.0" />
            <geometry>
                <mesh filename="package://Sirius_description/meshes/Right_Wheel.stl" scale="0.001 0.001 0.001" />
            </geometry>
        </visual>
        <collision name="Right_Wheel_collision">
            <origin xyz="0.015 -0.27 -0.18" rpy="1.5707963267948966 -0.0 0.0" />
            <geometry>
                <mesh filename="package://Sirius_description/meshes/Right_Wheel.stl" scale="0.001 0.001 0.001" />
            </geometry>
        </collision>
    </link>
    <link name="LiDAR_Support">
        <inertial>
            <origin xyz="-0.052820883669245824 1.1537955902002506e-16 0.3425" rpy="0.0 0.0 0.0" />
            <mass value="0.3093933392343076" />
            <inertia ixx="0.0005861375596076246" iyy="0.000575193141818392" izz="0.0011600415625125382" ixy="-8.146523068880001e-19" iyz="-8.366640713575181e-19" ixz="-1.734723475976807e-18" />
        </inertial>
        <visual name="LiDAR_Support_visual">
            <origin xyz="0.0 0.0 0.0" rpy="0.0 0.0 0.0" />
            <geometry>
                <mesh filename="package://Sirius_description/meshes/LiDAR_Support.stl" scale="0.001 0.001 0.001" />
            </geometry>
        </visual>
        <collision name="LiDAR_Support_collision">
            <origin xyz="0.0 0.0 0.0" rpy="0.0 0.0 0.0" />
            <geometry>
                <mesh filename="package://Sirius_description/meshes/LiDAR_Support.stl" scale="0.001 0.001 0.001" />
            </geometry>
        </collision>
    </link>
    <link name="LiDAR">
        <inertial>
            <origin xyz="-0.07 -2.4125096250508447e-17 0.37599999999999995" rpy="0.0 0.0 0.0" />
            <mass value="4.439070419522379" />
            <inertia ixx="0.004692097433435238" iyy="0.004692097433435571" izz="0.005548838024402897" ixy="-1.0709300113376216e-18" iyz="-1.7134880181401884e-18" ixz="0.0" />
        </inertial>
        <visual name="LiDAR_visual">
            <origin xyz="0.0 0.0 0.0" rpy="0.0 0.0 0.0" />
            <geometry>
                <mesh filename="package://Sirius_description/meshes/LiDAR.stl" scale="0.001 0.001 0.001" />
            </geometry>
        </visual>
        <collision name="LiDAR_collision">
            <origin xyz="0.0 0.0 0.0" rpy="0.0 0.0 0.0" />
            <geometry>
                <mesh filename="package://Sirius_description/meshes/LiDAR.stl" scale="0.001 0.001 0.001" />
            </geometry>
        </collision>
    </link>
    <link name="Display">
        <inertial>
            <origin xyz="0.009999999999999998 0.0 0.16" rpy="0.0 0.0 0.0" />
            <mass value="13.941599999999996" />
            <inertia ixx="0.22597009999999979" iyy="0.06738439999999996" izz="0.1595151399999998" ixy="0.0" iyz="4.5693013817071915e-17" ixz="3.469446951953614e-18" />
        </inertial>
        <visual name="Display_visual">
            <origin xyz="0.0 0.0 0.0" rpy="0.0 0.0 0.0" />
            <geometry>
                <mesh filename="package://Sirius_description/meshes/Display.stl" scale="0.001 0.001 0.001" />
            </geometry>
        </visual>
        <collision name="Display_collision">
            <origin xyz="0.0 0.0 0.0" rpy="0.0 0.0 0.0" />
            <geometry>
                <mesh filename="package://Sirius_description/meshes/Display.stl" scale="0.001 0.001 0.001" />
            </geometry>
        </collision>
    </link>
    <link name="Left_ESB">
        <inertial>
            <origin xyz="-0.014999999999999998 -0.21667604038411042 0.215" rpy="0.0 0.0 0.0" />
            <mass value="2.3621900233067987" />
            <inertia ixx="0.0017880560898025089" iyy="0.0017770425879946872" izz="0.0017880560898024533" ixy="0.0" iyz="0.0" ixz="-1.734723475976807e-18" />
        </inertial>
        <visual name="Left_ESB_visual">
            <origin xyz="0.0 0.0 0.0" rpy="0.0 0.0 0.0" />
            <geometry>
                <mesh filename="package://Sirius_description/meshes/Left_ESB.stl" scale="0.001 0.001 0.001" />
            </geometry>
        </visual>
        <collision name="Left_ESB_collision">
            <origin xyz="0.0 0.0 0.0" rpy="0.0 0.0 0.0" />
            <geometry>
                <mesh filename="package://Sirius_description/meshes/Left_ESB.stl" scale="0.001 0.001 0.001" />
            </geometry>
        </collision>
    </link>
    <link name="Right_ESB">
        <inertial>
            <origin xyz="-0.014999999999999998 0.21667604038411042 0.215" rpy="0.0 0.0 0.0" />
            <mass value="2.3621900233067987" />
            <inertia ixx="0.0017880560898025089" iyy="0.0017770425879946872" izz="0.001788056089802481" ixy="-1.734723475976807e-18" iyz="0.0" ixz="-1.734723475976807e-18" />
        </inertial>
        <visual name="Right_ESB_visual">
            <origin xyz="0.0 0.0 0.0" rpy="0.0 0.0 0.0" />
            <geometry>
                <mesh filename="package://Sirius_description/meshes/Right_ESB.stl" scale="0.001 0.001 0.001" />
            </geometry>
        </visual>
        <collision name="Right_ESB_collision">
            <origin xyz="0.0 0.0 0.0" rpy="0.0 0.0 0.0" />
            <geometry>
                <mesh filename="package://Sirius_description/meshes/Right_ESB.stl" scale="0.001 0.001 0.001" />
            </geometry>
        </collision>
    </link>
    <link name="Display_Bg">
        <inertial>
            <origin xyz="-0.014999999999999998 0.0 0.16863359351883772" rpy="0.0 0.0 0.0" />
            <mass value="29.373206337400482" />
            <inertia ixx="0.6092684729448462" iyy="0.2811472839601523" izz="0.3325271699353042" ixy="2.2846506908535957e-17" iyz="0.0" ixz="1.3877787807814457e-17" />
        </inertial>
        <visual name="Display_Bg_visual">
            <origin xyz="0.0 0.0 0.0" rpy="0.0 0.0 0.0" />
            <geometry>
                <mesh filename="package://Sirius_description/meshes/Display_Bg.stl" scale="0.001 0.001 0.001" />
            </geometry>
        </visual>
        <collision name="Display_Bg_collision">
            <origin xyz="0.0 0.0 0.0" rpy="0.0 0.0 0.0" />
            <geometry>
                <mesh filename="package://Sirius_description/meshes/Display_Bg.stl" scale="0.001 0.001 0.001" />
            </geometry>
        </collision>
    </link>
    <link name="Case">
        <inertial>
            <origin xyz="0.17500000000000002 0.0 0.035" rpy="0.0 0.0 0.0" />
            <mass value="83.79874999999998" />
            <inertia ixx="2.6326773958333343" iyy="0.47066964583333304" izz="3.034911395833333" ixy="0.0" iyz="-1.8277205526828766e-16" ixz="1.1102230246251565e-16" />
        </inertial>
        <visual name="Case_visual">
            <origin xyz="0.0 0.0 0.0" rpy="0.0 0.0 0.0" />
            <geometry>
                <mesh filename="package://Sirius_description/meshes/Case.stl" scale="0.001 0.001 0.001" />
            </geometry>
        </visual>
        <collision name="Case_collision">
            <origin xyz="0.0 0.0 0.0" rpy="0.0 0.0 0.0" />
            <geometry>
                <mesh filename="package://Sirius_description/meshes/Case.stl" scale="0.001 0.001 0.001" />
            </geometry>
        </collision>
    </link>
    <link name="Left_Wheel">
        <inertial>
            <origin xyz="-2.4424906541753444e-17 -3.552713678800501e-17 0.0625" rpy="0.0 -0.0 0.0" />
            <mass value="100.05890789374806" />
            <inertia ixx="0.9387204983052886" iyy="0.9387204983053437" izz="1.6349121401939106" ixy="-1.9984014443252818e-15" iyz="-2.6645352591003757e-15" ixz="-5.551115123125783e-17" />
        </inertial>
        <visual name="Left_Wheel_visual">
            <origin xyz="0.015 0.27 -0.18" rpy="-1.5707963267948966 -0.0 0.0" />
            <geometry>
                <mesh filename="package://Sirius_description/meshes/Left_Wheel.stl" scale="0.001 0.001 0.001" />
            </geometry>
        </visual>
        <collision name="Left_Wheel_collision">
            <origin xyz="0.015 0.27 -0.18" rpy="-1.5707963267948966 -0.0 0.0" />
            <geometry>
                <mesh filename="package://Sirius_description/meshes/Left_Wheel.stl" scale="0.001 0.001 0.001" />
            </geometry>
        </collision>
    </link>
    <link name="Frame">
        <inertial>
            <origin xyz="0.02336046562605979 -3.391591384159738e-16 -0.22499410556332286" rpy="0.0 0.0 0.0" />
            <mass value="121.25196634073023" />
            <inertia ixx="4.632371381951651" iyy="7.237356930641641" izz="8.42852456545905" ixy="-2.4355492145103126e-14" iyz="-9.826421981859261e-16" ixz="0.4667578254363328" />
        </inertial>
        <visual name="Frame_visual">
            <origin xyz="0.0 0.0 0.0" rpy="0.0 0.0 0.0" />
            <geometry>
                <mesh filename="package://Sirius_description/meshes/Frame.stl" scale="0.001 0.001 0.001" />
            </geometry>
        </visual>
        <collision name="Frame_collision">
            <origin xyz="0.0 0.0 0.0" rpy="0.0 0.0 0.0" />
            <geometry>
                <mesh filename="package://Sirius_description/meshes/Frame.stl" scale="0.001 0.001 0.001" />
            </geometry>
        </collision>
    </link>
    <joint name="Frame_to_Case" type="fixed">
        <origin xyz="0.0 0.0 0.0" rpy="0.0 0.0 0.0" />
        <parent link="Frame" />
        <child link="Case" />
    </joint>
    <joint name="Frame_to_Display" type="fixed">
        <origin xyz="0.0 0.0 0.0" rpy="0.0 0.0 0.0" />
        <parent link="Frame" />
        <child link="Display" />
    </joint>
    <joint name="Frame_to_Display_Bg" type="fixed">
        <origin xyz="0.0 0.0 0.0" rpy="0.0 0.0 0.0" />
        <parent link="Frame" />
        <child link="Display_Bg" />
    </joint>
    <joint name="Frame_to_LiDAR_Support" type="fixed">
        <origin xyz="0.0 0.0 0.0" rpy="0.0 0.0 0.0" />
        <parent link="Frame" />
        <child link="LiDAR_Support" />
    </joint>
    <joint name="Frame_to_LiDAR" type="fixed">
        <origin xyz="0.0 0.0 0.0" rpy="0.0 0.0 0.0" />
        <parent link="Frame" />
        <child link="LiDAR" />
    </joint>
    <joint name="Frame_to_Left_ESB" type="fixed">
        <origin xyz="0.0 0.0 0.0" rpy="0.0 0.0 0.0" />
        <parent link="Frame" />
        <child link="Left_ESB" />
    </joint>
    <joint name="Frame_to_Right_ESB" type="fixed">
        <origin xyz="0.0 0.0 0.0" rpy="0.0 0.0 0.0" />
        <parent link="Frame" />
        <child link="Right_ESB" />
    </joint>
    <joint name="Frame_to_MDF" type="fixed">
        <origin xyz="0.0 0.0 0.0" rpy="0.0 0.0 0.0" />
        <parent link="Frame" />
        <child link="MDF" />
    </joint>

    <link name="Caster">
        <inertial>
            <origin xyz="0.0 0.0 0.0" rpy="0.0 0.0 0.0" />
            <mass value="1.0" />
            <inertia ixx="0.001" iyy="0.001" izz="0.001" ixy="0.0" iyz="0.0" ixz="0.0" />
        </inertial>
        <visual name="Caster_visual">
            <origin xyz="0.0 0.0 0.0" rpy="0.0 0.0 0.0" />
            <geometry>
                <sphere radius="0.05" />
            </geometry>
        </visual>
        <collision name="Caster_collision">
            <origin xyz="0.0 0.0 0.0" rpy="0.0 0.0 0.0" />
            <geometry>
                <sphere radius="0.05" />
            </geometry>
        </collision>
    </link>

    <joint name="Frame_to_Caster" type="continuous">
        <origin xyz="0.4 0.0 -0.40" rpy="0.0 0.0 0.0" />
        <parent link="Frame" />
        <child link="Caster" />
        <axis xyz="0 0 1" />
    </joint>
    <joint name="Frame_Revolute-5" type="continuous">
        <origin xyz="-0.015 -0.18 -0.27" rpy="1.5707963267948966 -0.0 0.0" />
        <parent link="Frame" />
        <child link="Left_Wheel" />
        <axis xyz="0.0 0.0 1.0" />
    </joint>
    <joint name="Frame_Revolute-6" type="continuous">
        <origin xyz="-0.015 0.18 -0.27" rpy="-1.5707963267948966 -0.0 0.0" />
        <parent link="Frame" />
        <child link="Right_Wheel" />
        <axis xyz="0.0 0.0 -1.0" />
    </joint>
</robot>